2024-06-24 06:40:20,417 - distributed.nanny - INFO -         Start Nanny at: 'tcp://128.117.208.89:46465'
2024-06-24 06:40:25,902 - distributed.worker - INFO -       Start worker at: tcp://128.117.208.89:35277
2024-06-24 06:40:25,902 - distributed.worker - INFO -          Listening to: tcp://128.117.208.89:35277
2024-06-24 06:40:25,902 - distributed.worker - INFO -           Worker name:               PBSCluster-0
2024-06-24 06:40:25,902 - distributed.worker - INFO -          dashboard at:       128.117.208.89:41721
2024-06-24 06:40:25,902 - distributed.worker - INFO - Waiting to connect to: tcp://128.117.208.102:45151
2024-06-24 06:40:25,902 - distributed.worker - INFO - -------------------------------------------------
2024-06-24 06:40:25,902 - distributed.worker - INFO -               Threads:                          1
2024-06-24 06:40:25,902 - distributed.worker - INFO -                Memory:                   9.31 GiB
2024-06-24 06:40:25,902 - distributed.worker - INFO -       Local Directory: /glade/derecho/scratch/mdfowler/tmp/dask-scratch-space/worker-1r7_f6ls
2024-06-24 06:40:25,902 - distributed.worker - INFO - -------------------------------------------------
2024-06-24 06:40:29,282 - distributed.worker - INFO - Starting Worker plugin shuffle
2024-06-24 06:40:29,284 - distributed.worker - INFO -         Registered to: tcp://128.117.208.102:45151
2024-06-24 06:40:29,284 - distributed.worker - INFO - -------------------------------------------------
2024-06-24 06:40:29,284 - distributed.core - INFO - Starting established connection to tcp://128.117.208.102:45151
ERROR 1: PROJ: proj_create_from_database: Open of /glade/u/apps/opt/conda/envs/npl-2024a/share/proj failed
/glade/derecho/scratch/mdfowler/tmp/ipykernel_68900/2848046507.py:10: RuntimeWarning: Converting a CFTimeIndex with dates from a non-standard calendar, 'noleap', to a pandas.DatetimeIndex, which uses dates from the standard calendar.  This may lead to subtle errors in operations that depend on the length of time between dates.
/glade/derecho/scratch/mdfowler/tmp/ipykernel_68900/2848046507.py:33: RuntimeWarning: Converting a CFTimeIndex with dates from a non-standard calendar, 'noleap', to a pandas.DatetimeIndex, which uses dates from the standard calendar.  This may lead to subtle errors in operations that depend on the length of time between dates.
/glade/derecho/scratch/mdfowler/tmp/ipykernel_68900/2848046507.py:33: RuntimeWarning: Converting a CFTimeIndex with dates from a non-standard calendar, 'noleap', to a pandas.DatetimeIndex, which uses dates from the standard calendar.  This may lead to subtle errors in operations that depend on the length of time between dates.
/glade/derecho/scratch/mdfowler/tmp/ipykernel_68900/2848046507.py:33: RuntimeWarning: Converting a CFTimeIndex with dates from a non-standard calendar, 'noleap', to a pandas.DatetimeIndex, which uses dates from the standard calendar.  This may lead to subtle errors in operations that depend on the length of time between dates.
/glade/derecho/scratch/mdfowler/tmp/ipykernel_68900/2848046507.py:33: RuntimeWarning: Converting a CFTimeIndex with dates from a non-standard calendar, 'noleap', to a pandas.DatetimeIndex, which uses dates from the standard calendar.  This may lead to subtle errors in operations that depend on the length of time between dates.
/glade/derecho/scratch/mdfowler/tmp/ipykernel_68900/2848046507.py:33: RuntimeWarning: Converting a CFTimeIndex with dates from a non-standard calendar, 'noleap', to a pandas.DatetimeIndex, which uses dates from the standard calendar.  This may lead to subtle errors in operations that depend on the length of time between dates.
/glade/derecho/scratch/mdfowler/tmp/ipykernel_68900/2848046507.py:33: RuntimeWarning: Converting a CFTimeIndex with dates from a non-standard calendar, 'noleap', to a pandas.DatetimeIndex, which uses dates from the standard calendar.  This may lead to subtle errors in operations that depend on the length of time between dates.
/glade/derecho/scratch/mdfowler/tmp/ipykernel_68900/2848046507.py:33: RuntimeWarning: Converting a CFTimeIndex with dates from a non-standard calendar, 'noleap', to a pandas.DatetimeIndex, which uses dates from the standard calendar.  This may lead to subtle errors in operations that depend on the length of time between dates.
2024-06-24 06:48:44,715 - distributed.core - INFO - Connection to tcp://128.117.208.102:45151 has been closed.
2024-06-24 06:48:44,718 - distributed.worker - INFO - Stopping worker at tcp://128.117.208.89:35277. Reason: worker-handle-scheduler-connection-broken
2024-06-24 06:48:44,721 - distributed.worker - ERROR - Failed to communicate with scheduler during heartbeat.
Traceback (most recent call last):
  File "/glade/u/apps/opt/conda/envs/npl-2024a/lib/python3.11/site-packages/tornado/iostream.py", line 861, in _read_to_buffer
    bytes_read = self.read_from_fd(buf)
                 ^^^^^^^^^^^^^^^^^^^^^^
  File "/glade/u/apps/opt/conda/envs/npl-2024a/lib/python3.11/site-packages/tornado/iostream.py", line 1116, in read_from_fd
    return self.socket.recv_into(buf, len(buf))
           ^^^^^^^^^^^^^^^^^^^^^^^^^^^^^^^^^^^^
ConnectionResetError: [Errno 104] Connection reset by peer

The above exception was the direct cause of the following exception:

Traceback (most recent call last):
  File "/glade/u/apps/opt/conda/envs/npl-2024a/lib/python3.11/site-packages/distributed/worker.py", line 1252, in heartbeat
    response = await retry_operation(
               ^^^^^^^^^^^^^^^^^^^^^^
  File "/glade/u/apps/opt/conda/envs/npl-2024a/lib/python3.11/site-packages/distributed/utils_comm.py", line 455, in retry_operation
    return await retry(
           ^^^^^^^^^^^^
  File "/glade/u/apps/opt/conda/envs/npl-2024a/lib/python3.11/site-packages/distributed/utils_comm.py", line 434, in retry
    return await coro()
           ^^^^^^^^^^^^
  File "/glade/u/apps/opt/conda/envs/npl-2024a/lib/python3.11/site-packages/distributed/core.py", line 1391, in send_recv_from_rpc
    comm = await self.pool.connect(self.addr)
           ^^^^^^^^^^^^^^^^^^^^^^^^^^^^^^^^^^
  File "/glade/u/apps/opt/conda/envs/npl-2024a/lib/python3.11/site-packages/distributed/core.py", line 1619, in connect
    return await self._connect(addr=addr, timeout=timeout)
           ^^^^^^^^^^^^^^^^^^^^^^^^^^^^^^^^^^^^^^^^^^^^^^^
  File "/glade/u/apps/opt/conda/envs/npl-2024a/lib/python3.11/site-packages/distributed/core.py", line 1563, in _connect
    comm = await connect(
           ^^^^^^^^^^^^^^
  File "/glade/u/apps/opt/conda/envs/npl-2024a/lib/python3.11/site-packages/distributed/comm/core.py", line 377, in connect
    handshake = await comm.read()
                ^^^^^^^^^^^^^^^^^
  File "/glade/u/apps/opt/conda/envs/npl-2024a/lib/python3.11/site-packages/distributed/comm/tcp.py", line 237, in read
    convert_stream_closed_error(self, e)
  File "/glade/u/apps/opt/conda/envs/npl-2024a/lib/python3.11/site-packages/distributed/comm/tcp.py", line 140, in convert_stream_closed_error
    raise CommClosedError(f"in {obj}: {exc.__class__.__name__}: {exc}") from exc
distributed.comm.core.CommClosedError: in <TCP (closed)  local=tcp://128.117.208.89:40400 remote=tcp://128.117.208.102:45151>: ConnectionResetError: [Errno 104] Connection reset by peer
2024-06-24 06:48:44,801 - distributed.nanny - INFO - Closing Nanny gracefully at 'tcp://128.117.208.89:46465'. Reason: worker-handle-scheduler-connection-broken
2024-06-24 06:48:46,915 - distributed.client - ERROR - 
ConnectionRefusedError: [Errno 111] Connection refused

The above exception was the direct cause of the following exception:

Traceback (most recent call last):
  File "/glade/u/apps/opt/conda/envs/npl-2024a/lib/python3.11/site-packages/distributed/comm/core.py", line 342, in connect
    comm = await wait_for(
           ^^^^^^^^^^^^^^^
  File "/glade/u/apps/opt/conda/envs/npl-2024a/lib/python3.11/site-packages/distributed/utils.py", line 1935, in wait_for
    return await fut
           ^^^^^^^^^
  File "/glade/u/apps/opt/conda/envs/npl-2024a/lib/python3.11/site-packages/distributed/comm/tcp.py", line 560, in connect
    convert_stream_closed_error(self, e)
  File "/glade/u/apps/opt/conda/envs/npl-2024a/lib/python3.11/site-packages/distributed/comm/tcp.py", line 140, in convert_stream_closed_error
    raise CommClosedError(f"in {obj}: {exc.__class__.__name__}: {exc}") from exc
distributed.comm.core.CommClosedError: in <distributed.comm.tcp.TCPConnector object at 0x1548e7997010>: ConnectionRefusedError: [Errno 111] Connection refused

During handling of the above exception, another exception occurred:

Traceback (most recent call last):
  File "/glade/u/apps/opt/conda/envs/npl-2024a/lib/python3.11/site-packages/distributed/utils.py", line 832, in wrapper
    return await func(*args, **kwargs)
           ^^^^^^^^^^^^^^^^^^^^^^^^^^^
  File "/glade/u/apps/opt/conda/envs/npl-2024a/lib/python3.11/site-packages/distributed/client.py", line 1328, in _reconnect
    await self._ensure_connected(timeout=timeout)
  File "/glade/u/apps/opt/conda/envs/npl-2024a/lib/python3.11/site-packages/distributed/client.py", line 1358, in _ensure_connected
    comm = await connect(
           ^^^^^^^^^^^^^^
  File "/glade/u/apps/opt/conda/envs/npl-2024a/lib/python3.11/site-packages/distributed/comm/core.py", line 366, in connect
    await asyncio.sleep(backoff)
  File "/glade/u/apps/opt/conda/envs/npl-2024a/lib/python3.11/asyncio/tasks.py", line 649, in sleep
    return await future
           ^^^^^^^^^^^^
asyncio.exceptions.CancelledError
2024-06-24 06:48:46,924 - distributed.nanny - INFO - Worker closed
2024-06-24 06:48:50,867 - distributed.nanny - INFO - Closing Nanny at 'tcp://128.117.208.89:46465'. Reason: nanny-close-gracefully
2024-06-24 06:48:50,869 - distributed.dask_worker - INFO - End worker
