2024-06-27 08:12:57,221 - distributed.nanny - INFO -         Start Nanny at: 'tcp://128.117.208.62:36889'
2024-06-27 08:13:00,933 - distributed.worker - INFO -       Start worker at: tcp://128.117.208.62:38017
2024-06-27 08:13:00,933 - distributed.worker - INFO -          Listening to: tcp://128.117.208.62:38017
2024-06-27 08:13:00,934 - distributed.worker - INFO -           Worker name:              PBSCluster-23
2024-06-27 08:13:00,934 - distributed.worker - INFO -          dashboard at:       128.117.208.62:41067
2024-06-27 08:13:00,934 - distributed.worker - INFO - Waiting to connect to: tcp://128.117.208.86:37311
2024-06-27 08:13:00,934 - distributed.worker - INFO - -------------------------------------------------
2024-06-27 08:13:00,934 - distributed.worker - INFO -               Threads:                          1
2024-06-27 08:13:00,934 - distributed.worker - INFO -                Memory:                   3.73 GiB
2024-06-27 08:13:00,934 - distributed.worker - INFO -       Local Directory: /glade/derecho/scratch/mdfowler/tmp/dask-scratch-space/worker-fn4h0i3a
2024-06-27 08:13:00,934 - distributed.worker - INFO - -------------------------------------------------
2024-06-27 08:13:18,568 - distributed.worker - INFO - Starting Worker plugin shuffle
2024-06-27 08:13:18,570 - distributed.worker - INFO -         Registered to: tcp://128.117.208.86:37311
2024-06-27 08:13:18,570 - distributed.worker - INFO - -------------------------------------------------
2024-06-27 08:13:18,571 - distributed.core - INFO - Starting established connection to tcp://128.117.208.86:37311
2024-06-27 09:12:37,456 - distributed.core - INFO - Event loop was unresponsive in Worker for 3.71s.  This is often caused by long-running GIL-holding functions or moving large chunks of data. This can cause timeouts and instability.
2024-06-27 09:12:50,369 - distributed.worker.memory - WARNING - Worker is at 86% memory usage. Pausing worker.  Process memory: 3.22 GiB -- Worker memory limit: 3.73 GiB
2024-06-27 09:12:50,715 - distributed.worker.memory - WARNING - Unmanaged memory use is high. This may indicate a memory leak or the memory may not be released to the OS; see https://distributed.dask.org/en/latest/worker-memory.html#memory-not-released-back-to-the-os for more information. -- Unmanaged memory: 3.41 GiB -- Worker memory limit: 3.73 GiB
2024-06-27 09:12:50,715 - distributed.core - INFO - Event loop was unresponsive in Worker for 4.55s.  This is often caused by long-running GIL-holding functions or moving large chunks of data. This can cause timeouts and instability.
2024-06-27 09:12:50,876 - distributed.worker.memory - WARNING - Worker is at 7% memory usage. Resuming worker. Process memory: 273.36 MiB -- Worker memory limit: 3.73 GiB
2024-06-27 09:17:47,905 - distributed.worker.memory - WARNING - Worker is at 91% memory usage. Pausing worker.  Process memory: 3.40 GiB -- Worker memory limit: 3.73 GiB
2024-06-27 09:17:48,595 - distributed.worker.memory - WARNING - Worker is at 48% memory usage. Resuming worker. Process memory: 1.79 GiB -- Worker memory limit: 3.73 GiB
2024-06-27 09:26:35,269 - distributed.nanny.memory - WARNING - Worker tcp://128.117.208.62:38017 (pid=19955) exceeded 95% memory budget. Restarting...
2024-06-27 09:26:35,293 - distributed.nanny - INFO - Worker process 19955 was killed by signal 15
2024-06-27 09:26:35,298 - distributed.nanny - WARNING - Restarting worker
2024-06-27 09:26:40,463 - distributed.worker - INFO -       Start worker at: tcp://128.117.208.62:44433
2024-06-27 09:26:40,465 - distributed.worker - INFO -          Listening to: tcp://128.117.208.62:44433
2024-06-27 09:26:40,465 - distributed.worker - INFO -           Worker name:              PBSCluster-23
2024-06-27 09:26:40,465 - distributed.worker - INFO -          dashboard at:       128.117.208.62:33003
2024-06-27 09:26:40,465 - distributed.worker - INFO - Waiting to connect to: tcp://128.117.208.86:37311
2024-06-27 09:26:40,465 - distributed.worker - INFO - -------------------------------------------------
2024-06-27 09:26:40,468 - distributed.worker - INFO -               Threads:                          1
2024-06-27 09:26:40,468 - distributed.worker - INFO -                Memory:                   3.73 GiB
2024-06-27 09:26:40,468 - distributed.worker - INFO -       Local Directory: /glade/derecho/scratch/mdfowler/tmp/dask-scratch-space/worker-pwpat3zp
2024-06-27 09:26:40,468 - distributed.worker - INFO - -------------------------------------------------
2024-06-27 09:26:41,259 - distributed.worker - INFO - Starting Worker plugin shuffle
2024-06-27 09:26:41,260 - distributed.worker - INFO -         Registered to: tcp://128.117.208.86:37311
2024-06-27 09:26:41,260 - distributed.worker - INFO - -------------------------------------------------
2024-06-27 09:26:41,261 - distributed.core - INFO - Starting established connection to tcp://128.117.208.86:37311
2024-06-27 10:54:40,916 - distributed.worker - ERROR - Worker stream died during communication: tcp://128.117.208.106:45739
ConnectionRefusedError: [Errno 111] Connection refused

The above exception was the direct cause of the following exception:

Traceback (most recent call last):
  File "/glade/u/apps/opt/conda/envs/npl-2024a/lib/python3.11/site-packages/distributed/comm/core.py", line 342, in connect
    comm = await wait_for(
           ^^^^^^^^^^^^^^^
  File "/glade/u/apps/opt/conda/envs/npl-2024a/lib/python3.11/site-packages/distributed/utils.py", line 1935, in wait_for
    return await fut
           ^^^^^^^^^
  File "/glade/u/apps/opt/conda/envs/npl-2024a/lib/python3.11/site-packages/distributed/comm/tcp.py", line 560, in connect
    convert_stream_closed_error(self, e)
  File "/glade/u/apps/opt/conda/envs/npl-2024a/lib/python3.11/site-packages/distributed/comm/tcp.py", line 140, in convert_stream_closed_error
    raise CommClosedError(f"in {obj}: {exc.__class__.__name__}: {exc}") from exc
distributed.comm.core.CommClosedError: in <distributed.comm.tcp.TCPConnector object at 0x1531e4aa2790>: ConnectionRefusedError: [Errno 111] Connection refused

The above exception was the direct cause of the following exception:

Traceback (most recent call last):
  File "/glade/u/apps/opt/conda/envs/npl-2024a/lib/python3.11/site-packages/distributed/worker.py", line 2056, in gather_dep
    response = await get_data_from_worker(
               ^^^^^^^^^^^^^^^^^^^^^^^^^^^
  File "/glade/u/apps/opt/conda/envs/npl-2024a/lib/python3.11/site-packages/distributed/worker.py", line 2857, in get_data_from_worker
    comm = await rpc.connect(worker)
           ^^^^^^^^^^^^^^^^^^^^^^^^^
  File "/glade/u/apps/opt/conda/envs/npl-2024a/lib/python3.11/site-packages/distributed/core.py", line 1619, in connect
    return await self._connect(addr=addr, timeout=timeout)
           ^^^^^^^^^^^^^^^^^^^^^^^^^^^^^^^^^^^^^^^^^^^^^^^
  File "/glade/u/apps/opt/conda/envs/npl-2024a/lib/python3.11/site-packages/distributed/core.py", line 1563, in _connect
    comm = await connect(
           ^^^^^^^^^^^^^^
  File "/glade/u/apps/opt/conda/envs/npl-2024a/lib/python3.11/site-packages/distributed/comm/core.py", line 368, in connect
    raise OSError(
OSError: Timed out trying to connect to tcp://128.117.208.106:45739 after 30 s
2024-06-27 11:01:23,782 - distributed.core - INFO - Connection to tcp://128.117.208.86:37311 has been closed.
2024-06-27 11:01:23,783 - distributed.worker - INFO - Stopping worker at tcp://128.117.208.62:44433. Reason: worker-handle-scheduler-connection-broken
2024-06-27 11:01:23,795 - distributed.nanny - INFO - Closing Nanny gracefully at 'tcp://128.117.208.62:36889'. Reason: worker-handle-scheduler-connection-broken
2024-06-27 11:01:23,797 - distributed.worker - ERROR - Failed to communicate with scheduler during heartbeat.
Traceback (most recent call last):
  File "/glade/u/apps/opt/conda/envs/npl-2024a/lib/python3.11/site-packages/distributed/comm/tcp.py", line 225, in read
    frames_nosplit_nbytes_bin = await stream.read_bytes(fmt_size)
                                ^^^^^^^^^^^^^^^^^^^^^^^^^^^^^^^^^
tornado.iostream.StreamClosedError: Stream is closed

The above exception was the direct cause of the following exception:

Traceback (most recent call last):
  File "/glade/u/apps/opt/conda/envs/npl-2024a/lib/python3.11/site-packages/distributed/worker.py", line 1252, in heartbeat
    response = await retry_operation(
               ^^^^^^^^^^^^^^^^^^^^^^
  File "/glade/u/apps/opt/conda/envs/npl-2024a/lib/python3.11/site-packages/distributed/utils_comm.py", line 455, in retry_operation
    return await retry(
           ^^^^^^^^^^^^
  File "/glade/u/apps/opt/conda/envs/npl-2024a/lib/python3.11/site-packages/distributed/utils_comm.py", line 434, in retry
    return await coro()
           ^^^^^^^^^^^^
  File "/glade/u/apps/opt/conda/envs/npl-2024a/lib/python3.11/site-packages/distributed/core.py", line 1394, in send_recv_from_rpc
    return await send_recv(comm=comm, op=key, **kwargs)
           ^^^^^^^^^^^^^^^^^^^^^^^^^^^^^^^^^^^^^^^^^^^^
  File "/glade/u/apps/opt/conda/envs/npl-2024a/lib/python3.11/site-packages/distributed/core.py", line 1153, in send_recv
    response = await comm.read(deserializers=deserializers)
               ^^^^^^^^^^^^^^^^^^^^^^^^^^^^^^^^^^^^^^^^^^^^
  File "/glade/u/apps/opt/conda/envs/npl-2024a/lib/python3.11/site-packages/distributed/comm/tcp.py", line 237, in read
    convert_stream_closed_error(self, e)
  File "/glade/u/apps/opt/conda/envs/npl-2024a/lib/python3.11/site-packages/distributed/comm/tcp.py", line 142, in convert_stream_closed_error
    raise CommClosedError(f"in {obj}: {exc}") from exc
distributed.comm.core.CommClosedError: in <TCP (closed) ConnectionPool.heartbeat_worker local=tcp://128.117.208.62:45712 remote=tcp://128.117.208.86:37311>: Stream is closed
2024-06-27 11:01:23,802 - distributed.nanny - INFO - Worker closed
2024-06-27 11:01:27,727 - distributed.nanny - INFO - Closing Nanny at 'tcp://128.117.208.62:36889'. Reason: nanny-close-gracefully
2024-06-27 11:01:27,728 - distributed.dask_worker - INFO - End worker
